Workbook

Sheet 年终奖分配明细表-国内
A1: 分配模式：人民币 (Currency: CNY) | AB1: =AC3-AC4 | AC1: T+T0 | AD1: =AE3-AE4 | AO1: =AP3-AP4 | AU1: =AV3-AV4 | AW1: =AX3-AX4 | AY1: =AZ3-AZ4
AC2: CNY | AE2: CNY | AP2: CNY | AV2: CNY | AX2: CNY | AZ2: CNY
A3: 请勿隐藏绿色可调整列 | U3: 总额度 (Total) | AC3: 100
A4: Please DO NOT hide the Green column ! | U4: 已用额度 (Assigned) | AC4: 100 | AE4: =ROUND(AD9+AE7+IF(ISREF(INDIRECT("'年终奖分配明细表-海外'!A1")),'年终奖分配明细表-海外'!AD9,0),0) | AP4: =ROUND(AO9+AP7+IF(ISREF(INDIRECT("'年终奖分配明细表-海外'!A1")),'年终奖分配明细表-海外'!AO9,0),0) | AV4: =ROUND(AU9+AV7+IF(ISREF(INDIRECT("'年终奖分配明细表-海外'!A1")),'年终奖分配明细表-海外'!AU9,0),0) | AX4: =ROUND(AW9+AX7+IF(ISREF(INDIRECT("'年终奖分配明细表-海外'!A1")),'年终奖分配明细表-海外'!AW9,0),0) | AZ4: =ROUND(AY9+AZ7+IF(ISREF(INDIRECT("'年终奖分配明细表-海外'!A1")),'年终奖分配明细表-海外'!AY9,0),0)
U5: 剩余额度 (Remaining) | AC5: =AC3-AC4 | AE5: =AE3-AE4 | AP5: =AP3-AP4 | AV5: =AV3-AV4 | AX5: =AX3-AX4 | AZ5: =AZ3-AZ4
AO6: =AP1 | AU6: =AV1 | AW6: =AX1 | AY6: =AZ1
A7: 请勿删除第一行到第七行！！！ | AB7: 21426647 | AC7: =AC3-AB7 | AE7: =AE3-AD7 | AP7: =AP3-AO7 | AV7: =AV3-AU7 | AX7: =AX3-AW7 | AZ7: =AZ3-AY7
E8: ="@@CURRENCY_CNY" | AC8: h+TkhcC+k1K03NEzw7PIuIzvrKpz8sw2bC8IRy/wu0I=
A9: 2 | G9: @@CD_g1qT4RWZn8PvzqzsvsSlZ1HoevUBl8dinYL8/H7Cw9JN1xdebvU/xUsX4kOF/8om | AB9: =SUM(AA14:AA128)+SUM(AC14:AC128) | AD9: =SUM(AE14:AE128) | AO9: =SUM(AP14:AP128) | AU9: =SUM(AV14:AV128) | AW9: =SUM(AX14:AX128) | AY9: =SUM(AZ14:AZ128)
H10: 基本信息 (Basic Info) | AC10: 本次奖金 (Bonus of This Year) | AO10: ="本次"&AP1 | AQ10: 本次合计 (Total of This Year) | BA10: 备注信息 (Remarks) | BG10: 辅助信息 (Additional Info) | BP10: 上年度参考信息 (Reference Info of Last Year) | CG10: 包信息 (Pool Info) | CI10: 自定义标签 (Custom Labels)
A11: Name | B11: Legal Name | C11: Staff ID | D11: Department | E11: Sub Organization of the Department | F11: 2nd-Level Org. Under Department | G11: Organization | H11: Onboarding Date | I11: Employment Type | J11: Job function | K11: Position | L11: Professional grade | M11: Managerial grade | N11: Talent Tier | O11: 2024 Talent Tier | P11: Talent Tier Change in Last 2 Years | Q11: 2025 H1/H2 Performance Ratings | R11: 2025 H1/H2 Customized Performance Ratings | S11: 2024 H1/H2 Performance Ratings | T11: Performance Change in Last 2 Years | U11: Current Monthly Salary (CNY) | V11: Target Bonus % | W11: Payroll Currency | X11: Time Proration Factor | Y11: Base Amount of Annual Bonus (CNY) | Z11: Base Amount of Target Bonus (CNY) | AA11: Target Bonus (T) (CNY) | AB11: Special Bonus (T0) Suggestion (CNY) | AC11: Actual Special Bonus (T0) (CNY) | AD11: =IF(ISBLANK(AD12),"预留",AD12)&CHAR(10)&"Suggestion"&CHAR(10)&"(CNY)" | AE11: =IF(ISBLANK(AD12),"预留",AD12)&CHAR(10)&"Submission"&CHAR(10)&"(CNY)" | AF11: Total Project Bonus (CNY) | AG11: T+T0 Bonus (CNY) | AH11: T+T0 Bonus Index | AI11: T+T0+Project Bonus Amount (CNY) | AJ11: T+T0+Project Bonus Index | AK11: Suggested T+T0+Project Bonus Index | AL11: Vs. 2024 T+T0+Project Bonus (CNY) | AM11: Target+Project Bonus Index | AN11: Suggested Target+Project Bonus Index | AO11: Incremental Profit Sharing Incentive Suggestion(CNY) (CNY) | AP11: =AO12&CHAR(10)&"Submission"&CHAR(10)&"(CNY)" | AQ11: Total Bonus Payout | AR11: Total Payout Index (China) | AS11: Vs. 2024 Total Bonus Payout | AT11: Total Payout Index (Overseas) | AU11: =IF(ISBLANK(AU12),"预留",AU12)&CHAR(10)&"Suggestion"&CHAR(10)&"(CNY)" | AV11: =AU12&CHAR(10)&"Submission"&CHAR(10)&"(CNY)" | AW11: =IF(ISBLANK(AW12),"预留",AW12)&CHAR(10)&"Suggestion"&CHAR(10)&"(CNY)" | AX11: =AW12&CHAR(10)&"Submission"&CHAR(10)&"(CNY)" | AY11: =IF(ISBLANK(AY12),"预留",AY12)&CHAR(10)&"Suggestion"&CHAR(10)&"(CNY)" | AZ11: =AY12&CHAR(10)&"Submission"&CHAR(10)&"(CNY)" | BA11: Allocation Remarks | BB11: Historical Remarks | BC11: C&B G Remarks | BD11: Remarks from HRBP | BE11: Compensation-Performance Consistency | BF11: Allocation Alert | BG11: Promised Bonus (CNY) | BH11: Bonus Paid During the Year (CNY) | BI11: Remarks about Paid Bonus | BJ11: Non-deductible Leave Days % | BK11: Leave Days Remarks | BL11: Time Proration Factor of 2024 Annual Bonus | BM11: Base Amount of 2024 Annual Bonus (CNY) | BN11: Base Amount of 2024 Target Bonus (CNY) | BO11: Monthly Salary in 2024 (CNY) | BP11: 2024 H1/H2 Performance Ratings | BQ11: 2024 Talent Tier | BR11: 2024 T+T0 Bonus (CNY) | BS11: 2024 T+T0 Bonus Index | BT11: 2024 Total Project Bonus (CNY) | BU11: 2024 T+T0+Project Bonus (CNY) | BV11: 2024 T+T0+Project Bonus Index | BW11: 2024 Target+Project Bonus Index | BX11: 2024 Incremental Incentive (CNY) | BY11: 2024 Total Bonus Payout (CNY) | BZ11: 2024 Total Payout Index (China) | CA11: 2024 Total Payout Index (Overseas) | CB11: 2024 Service Bonus (CNY) | CC11: 2024 One- time Incremental Incentive (CNY) | CD11: 2024 Special Grant (CNY) | CE11: 2024 Non-deductible Leave Days % | CF11: 2024 Salary Structure Change | CG11: Pool name | CH11: Pool Owner | CI11: Salary Structure Change | CJ11: Sheet Split Tag | CK11: Region | CL11: Country/Region | CM11: Continent Region | CN11: LCY Exchange Rate | CO11: Termination/Transfer Label | CP11: Organization Label | CQ11: Performance Label | CR11: Job Grade Label | CS11: Talent Tier Label | CT11: New Job System Label | CU11: Serious violations of the Sunshine Code of Conduct | CV11: Good Overall Performance Rating with Underperform Contribution or Conduct Rating | CW11: Backup Label 2 | CX11: Backup Label 3 | CY11: Backup Label 4 | CZ11: Backup Label 5 | DA11: Backup Label 6 | DB11: Backup Label 7 | DC11: Backup Label 8
A12: @Name | D12: ="@@CR_12" | AC12: ="@B_"&AC8 | AE12: ="@B_"&AE8 | AP12: ="@B_"&AP8 | AV12: ="@B_"&AV8 | AX12: ="@B_"&AX8 | AZ12: ="@B_"&AZ8 | BA12: ="@Remark"
A13: 中英文名 | B13: 真实姓名 | C13: 员工ID | D13: 部门 | E13: 部门下一级组织 | F13: 部门下二级组织 | G13: 组织全称 | H13: 入职日期 | I13: 应聘类别 | J13: 发展通道 | K13: 专业职位 | L13: 专业职级 | M13: 管理职级 | N13: 2025 人才梯队 | O13: 2024 人才梯队 | P13: 两年梯队变化 | Q13: 2025绩效 H1/H2 | R13: 2025自定义绩效 H1/H2 | S13: 2024绩效 H1/H2 | T13: 两年绩效变化 | U13: 目前月薪 (CNY) | V13: 浮动比例 | W13: 发薪币种 | X13: 年终奖 时间系数 | Y13: 年终奖 基数 (CNY) | Z13: Target Bonus基数 (CNY) | AA13: 绩效奖金 (T) (CNY) | AB13: 下发 特别奖金 (T0) (CNY) | AC13: 提交 特别奖金 (T0) (CNY) | AD13: ="下发"&CHAR(10)&IF(ISBLANK(AE1),"预留Q",AE1)&"(CNY)" | AE13: ="提交"&CHAR(10)&IF(ISBLANK(AE1),"预留R",AE1)&"(CNY)" | AF13: 项目奖金 合计 (CNY) | AG13: (T+T0) 金额 (CNY) | AH13: (T+T0) 系数 | AI13: (T+T0+项目奖) 金额 (CNY) | AJ13: (T+T0+项目奖) 系数 | AK13: 下发建议 (T+T0+项目奖) 系数 | AL13: VS 2024 (T+T0+项目奖) 金额 | AM13: (Target Bonus+项目奖)系数 | AN13: 下发建议 (Target Bonus+项目奖)系数 | AO13: ="下发"&CHAR(10)&AP1&"(CNY)" | AP13: ="提交"&CHAR(10)&AP1&"(CNY)" | AQ13: 合计金额 (CNY) | AR13: 国内合计系数 | AS13: VS 2024 合计金额 | AT13: 海外合计系数 | AU13: ="下发"&CHAR(10)&AV1&"(CNY)" | AV13: ="提交"&CHAR(10)&AV1&"(CNY)" | AW13: ="下发"&CHAR(10)&AX1&"(CNY)" | AX13: ="提交"&CHAR(10)&AX1&"(CNY)" | AY13: ="下发"&CHAR(10)&AZ1&"(CNY)" | AZ13: ="提交"&CHAR(10)&AZ1&"(CNY)" | BA13: 当前环节 分配备注 | BB13: 前序环节 分配备注 | BC13: 薪酬经理备注 | BD13: BP备注 | BE13: 薪酬与评价 匹配度 | BF13: 分配规则 校验信息 | BG13: 承诺奖金 (CNY) | BH13: 已发放奖金 (CNY) | BI13: 已发放奖金备注 | BJ13: 长假期天数占比(未影响时间系数) | BK13: 假期备注 | BL13: 2024 年终奖 时间系数 | BM13: 2024 年终奖 基数 (CNY) | BN13: 2024 Target Bonus基数 (CNY) | BO13: 2024月薪 (CNY) | BP13: 2024绩效 H1/H2 | BQ13: 2024 人才梯队 | BR13: 2024 (T+T0) 金额 (CNY) | BS13: 2024 (T+T0) 系数 | BT13: 2024 项目奖合计 (CNY) | BU13: 2024 (T+T0+项目奖) 金额 (CNY) | BV13: 2024 (T+T0+项目奖) 系数 | BW13: 2024 (Target Bonus+项目奖)系数 | BX13: 2024 增量激励 (如有) (CNY) | BY13: 2024 合计金额 (CNY) | BZ13: 2024 国内合计系数 | CA13: 2024 海外合计系数 | CB13: 2024 服务奖(CNY) | CC13: 2024增量项目激励 (如有) (CNY) | CD13: 2024年末特别授予(如有) (CNY) | CE13: 2024 长假期天数占比(未影响时间系数) | CF13: 2024全年 薪酬结构 变化标识 | CG13: 包名称 | CH13: 包负责人 | CI13: 全年 薪酬结构 变化标识 | CJ13: 拆表标签 | CK13: 地区分类 | CL13: 国家/地区 | CM13: 区域 | CN13: 本币汇率 | CO13: 离职/调动 标签 | CP13: 组织标签 | CQ13: 绩效标签 | CR13: 职级标签 | CS13: 梯队标签 | CT13: 试点体系标签 | CU13: 是否阳光行为违规 | CV13: 绩效综合G且业绩/行为评级U | CW13: 补充标签2 | CX13: 补充标签3 | CY13: 补充标签4 | CZ13: 补充标签5 | DA13: 补充标签6 | DB13: 补充标签7 | DC13: 补充标签8
A14: edwardXu(徐帆国) | C14: 57792341 | D14: 风险管理和内部控制 | E14: WXG风控中心 | G14: S2职能系统－财经线/风险管理和内部控制/WXG风控中心 | H14: 39707 | I14: 社会招聘 | J14: 财经类－FN | K14: 风险管理 | L14: S9 | N14: T1# | Q14: U,G | U14: 34220.45 | V14: 0.083333 | W14: CNY | X14: 1 | Y14: 32767.06 | Z14: 0 | AA14: 34220.45 | AB14: 112980 | AC14: 0 | AF14: 0 | AG14: 147200.45 | AH14: 4.4923301 | AI14: 147200.45 | AJ14: 4.4923301 | AK14: 4.4923301 | AQ14: 147200.45 | AR14: 4.4923301 | AS14: 0.64760427 | BL14: 1 | BM14: 30610 | BN14: 0 | BO14: 33125 | BP14: G,G | BQ14: T1# | BR14: 181445 | BS14: 5.927638 | BT14: 45855 | BU14: 227300 | BV14: 7.4256779 | BY14: 227300 | BZ14: 7.4256779 | CP14: 风险管理和内部控制 | CQ14: 3,1 | CR14: 9 | CS14: T1# | CT14: N
A15: savannahZhong(钟倩思) | C15: 78647818 | D15: 审计监察 | E15: 金融审计组 | G15: S2职能系统－财经线/审计监察/金融审计组 | H15: 45139 | I15: 高校招聘 | J15: 财经类－FN | K15: 风险管理 | L15: S5 | N15: T1# | Q15: G,U | U15: 23014.25 | V15: 0.083333 | W15: CNY | X15: 1 | Y15: 21659.73 | Z15: 0 | AA15: 69042.75 | AB15: 75165 | AC15: 24895 | AF15: 0 | AG15: 169102.75 | AH15: 7.8072418 | AI15: 169102.75 | AJ15: 7.8072418 | AK15: 6.6578739 | AQ15: 169102.75 | AR15: 7.8072418 | AS15: 21.652081 | BL15: 0.41643836 | BM15: 18765 | BN15: 0 | BO15: 18765 | BP15: N,G | BQ15: T1# | BR15: 7810 | BS15: 0.41620037 | BT15: 0 | BU15: 7810 | BV15: 0.41620037 | BY15: 7810 | BZ15: 0.41620037 | CP15: 审计监察 | CQ15: 5,3 | CR15: 5 | CS15: T1# | CT15: N
A16: emmaZheng(郑苑) | C16: 37559092 | D16: 财会及报告管理部 | E16: 应收管理中心 | G16: S2职能系统－财经线/财会及报告管理部/应收管理中心 | H16: 41779 | I16: 社会招聘 | J16: 财经类－FN | K16: 会计 | L16: S11 | N16: T1# | Q16: G,G | U16: 53212.6 | V16: 0.083333 | W16: CNY | X16: 1 | Y16: 50216.55 | Z16: 0 | AA16: 106425.2 | AB16: 166610 | AC16: 67765 | AF16: 0 | AG16: 340800.2 | AH16: 6.7866112 | AI16: 340800.2 | AJ16: 6.7866112 | AK16: 5.4371557 | AQ16: 340800.2 | AR16: 6.7866112 | AS16: 1.0573678 | BL16: 1 | BM16: 44240 | BN16: 0 | BO16: 46890 | BP16: G,G | BQ16: T1# | BR16: 235640 | BS16: 5.3264014 | BT16: 86670 | BU16: 322310 | BV16: 7.2854882 | BY16: 322310 | BZ16: 7.2854882 | CP16: 财会及报告管理部 | CQ16: 3,3 | CR16: 11 | CS16: T1# | CT16: N
A17: edwardJia(贾平华) | C17: 14198066 | D17: FiT财务管理 | E17: 业务支持与分析中心 | G17: S2职能系统－财经线/FiT财务管理/业务支持与分析中心 | H17: 37710 | I17: 社会招聘 | J17: 财经类－FN | K17: 财务管理 | L17: S6 | N17: T1 | Q17: O,G | U17: 27937.2 | V17: 0.083333 | W17: CNY | X17: 1 | Y17: 26626.57 | Z17: 0 | AA17: 111748.8 | AB17: 68640 | AC17: 42535 | AF17: 0 | AG17: 222923.8 | AH17: 8.3722312 | AI17: 222923.8 | AJ17: 8.3722312 | AK17: 6.7747667 | AQ17: 222923.8 | AR17: 8.3722312 | AS17: 1.6884969 | BL17: 1 | BM17: 23850 | BN17: 0 | BO17: 25715 | BP17: G,G | BQ17: T1 | BR17: 80825 | BS17: 3.3888889 | BT17: 51200 | BU17: 132025 | BV17: 5.5356394 | BY17: 132025 | BZ17: 5.5356394 | CP17: FiT财务管理 | CQ17: 5,5 | CR17: 6 | CS17: T1 | CT17: N
A18: patrickJiang(姜彪国) | C18: 1336290 | D18: 风险管理和内部控制 | E18: CSIG风控中心 | G18: S2职能系统－财经线/风险管理和内部控制/CSIG风控中心 | H18: 42286 | I18: 社会招聘 | J18: 财经类－FN | K18: 风险管理 | L18: S9 | N18: T1 | Q18: O,G | U18: 54594.65 | V18: 0.083333 | W18: CNY | X18: 1 | Y18: 53257.31 | Z18: 0 | AA18: 109189.3 | AB18: 130245 | AC18: 76345 | AF18: 0 | AG18: 315779.3 | AH18: 5.9293137 | AI18: 315779.3 | AJ18: 5.9293137 | AK18: 4.4958016 | AQ18: 315779.3 | AR18: 5.9293137 | AS18: 1.3897513 | BL18: 1 | BM18: 45345 | BN18: 0 | BO18: 49295 | BP18: G,G | BQ18: T1 | BR18: 155765 | BS18: 3.4351086 | BT18: 71455 | BU18: 227220 | BV18: 5.0109163 | BY18: 227220 | BZ18: 5.0109163 | CP18: 风险管理和内部控制 | CQ18: 3,3 | CR18: 9 | CS18: T1 | CT18: N
A19: chloeLin(林琴悦) | C19: 2185561 | D19: CSIG财务管理 | E19: 公线及费用财务管理中心 | G19: S2职能系统－财经线/CSIG财务管理/公线及费用财务管理中心 | H19: 43514 | I19: 社会招聘 | J19: 财经类－FN | K19: 财务管理 | L19: S8 | N19: T1 | Q19: O,G | U19: 46114.8 | V19: 0.083333 | W19: CNY | X19: 1 | Y19: 42227.05 | Z19: 0 | AA19: 138344.4 | AB19: 108735 | AC19: 68175 | AF19: 0 | AG19: 315254.4 | AH19: 7.4656979 | AI19: 315254.4 | AJ19: 7.4656979 | AK19: 5.8512115 | AQ19: 315254.4 | AR19: 7.4656979 | AS19: 1.2007404 | BL19: 1 | BM19: 38825 | BN19: 0 | BO19: 40225 | BP19: G,G | BQ19: T1# | BR19: 218440 | BS19: 5.6262717 | BT19: 44110 | BU19: 262550 | BV19: 6.7623954 | BY19: 262550 | BZ19: 6.7623954 | CP19: CSIG财务管理 | CQ19: 5,3 | CR19: 8 | CS19: T1 | CT19: N
A20: abigailDong(董璐月) | C20: 15958390 | D20: 风险管理和内部控制 | E20: IEG风控中心 | G20: S2职能系统－财经线/风险管理和内部控制/IEG风控中心 | H20: 37998 | I20: 高校招聘 | J20: 财经类－FN | K20: 风险管理 | L20: S11 | N20: T1 | Q20: G,O | U20: 42014.3 | V20: 0.083333 | W20: CNY | X20: 1 | Y20: 40908.92 | Z20: 0 | AA20: 42014.3 | AB20: 104350 | AC20: 0 | AF20: 0 | AG20: 146364.3 | AH20: 3.5778089 | AI20: 146364.3 | AJ20: 3.5778089 | AK20: 3.5778089 | AQ20: 146364.3 | AR20: 3.5778089 | AS20: 0.5545993 | BL20: 1 | BM20: 35120 | BN20: 0 | BO20: 37910 | BP20: G,G | BQ20: T1# | BR20: 207955 | BS20: 5.9212699 | BT20: 55955 | BU20: 263910 | BV20: 7.5145216 | BY20: 263910 | BZ20: 7.5145216 | CP20: 风险管理和内部控制 | CQ20: 3,1 | CR20: 11 | CS20: T1 | CT20: N
A21: nicholasQiu(邱强) | C21: 19081982 | D21: 风险管理和内部控制 | E21: IEG风控中心 | G21: S2职能系统－财经线/风险管理和内部控制/IEG风控中心 | H21: 42461 | I21: 高校招聘 | J21: 财经类－FN | K21: 风险管理 | L21: S8 | N21: T2 | Q21: G,G | U21: 44043.7 | V21: 0.083333 | W21: CNY | X21: 1 | Y21: 41123.76 | Z21: 0 | AA21: 132131.1 | AB21: 51655 | AC21: 0 | AF21: 0 | AG21: 183786.1 | AH21: 4.4690977 | AI21: 183786.1 | AJ21: 4.4690977 | AK21: 4.4690977 | AQ21: 183786.1 | AR21: 4.4690977 | AS21: 1.1295317 | BL21: 1 | BM21: 35815 | BN21: 0 | BO21: 38760 | BP21: G,O | BQ21: T2 | BR21: 162710 | BS21: 4.5430685 | BT21: 0 | BU21: 162710 | BV21: 4.5430685 | BY21: 162710 | BZ21: 4.5430685 | CP21: 风险管理和内部控制 | CQ21: 5,3 | CR21: 8 | CS21: T2 | CT21: N
A22: matthewHou(侯勋宏) | C22: 81154958 | D22: 海外财经中心 | E22: 海外本地财务 | G22: S2职能系统－财经线/海外财经中心/海外本地财务 | H22: 41263 | I22: 社会招聘 | J22: 财经类－FN | K22: 财务管理 | L22: S11 | N22: T1 | Q22: G,G | U22: 51306.95 | V22: 0.083333 | W22: CNY | X22: 1 | Y22: 46207.44 | Z22: 0 | AA22: 102613.9 | AB22: 108165 | AC22: 98095 | AF22: 0 | AG22: 308873.9 | AH22: 6.6845058 | AI22: 308873.9 | AJ22: 6.6845058 | AK22: 4.5615793 | AQ22: 308873.9 | AR22: 6.6845058 | AS22: 2.2710481 | BL22: 1 | BM22: 42530 | BN22: 0 | BO22: 44415 | BP22: U,O | BQ22: T1 | BR22: 136005 | BS22: 3.1978603 | BT22: 0 | BU22: 136005 | BV22: 3.1978603 | BY22: 136005 | BZ22: 3.1978603 | CP22: 海外财经中心 | CQ22: 3,3 | CR22: 11 | CS22: T1 | CT22: N
A23: lillianTian(田青) | C23: 21911153 | D23: 财经IT管理部 | E23: 平台建设中心 | G23: S2职能系统－财经线/财经IT管理部/平台建设中心 | H23: 43026 | I23: 高校招聘 | J23: 技术研发类－TRD | K23: 应用开发 | L23: T9 | N23: T1 | Q23: G,U | U23: 51577.2 | V23: 0.083333 | W23: CNY | X23: 1 | Y23: 47257.05 | Z23: 0 | AA23: 103154.4 | AB23: 128330 | AC23: 60530 | AF23: 0 | AG23: 292014.4 | AH23: 6.179277 | AI23: 292014.4 | AJ23: 6.179277 | AK23: 4.8984099 | AQ23: 292014.4 | AR23: 6.179277 | AS23: 1.4390262 | BL23: 1 | BM23: 43545 | BN23: 0 | BO23: 46510 | BP23: G,G | BQ23: T1 | BR23: 142185 | BS23: 3.2652429 | BT23: 60740 | BU23: 202925 | BV23: 4.6601217 | BY23: 202925 | BZ23: 4.6601217 | CP23: 财经IT管理部 | CQ23: 3,3 | CR23: 9 | CS23: T1 | CT23: N
A24: louisYu(于梓) | C24: 60316002 | D24: 预算及职能系统财务管理部 | E24: 预算及职能系统财务管理部 | G24: S2职能系统－财经线/预算及职能系统财务管理部 | H24: 39619 | I24: 社会招聘 | J24: 财经类－FN | K24: 预算管理 | L24: S6 | N24: T1# | Q24: O,G | U24: 24152.75 | V24: 0.083333 | W24: CNY | X24: 1 | Y24: 22085.21 | Z24: 0 | AA24: 48305.5 | AB24: 81310 | AC24: 41850 | AF24: 0 | AG24: 171465.5 | AH24: 7.7638157 | AI24: 171465.5 | AJ24: 7.7638157 | AK24: 5.8688824 | AQ24: 171465.5 | AR24: 7.7638157 | AS24: 1.0804379 | BL24: 1 | BM24: 21715 | BN24: 0 | BO24: 23560 | BP24: G,G | BQ24: T1# | BR24: 120875 | BS24: 5.5664287 | BT24: 37825 | BU24: 158700 | BV24: 7.3083122 | BY24: 158700 | BZ24: 7.3083122 | CP24: 预算及职能系统财务管理部 | CQ24: 3,3 | CR24: 6 | CS24: T1# | CT24: N
A25: ameliaNiu(牛佳娜) | C25: 82693967 | D25: 预算及职能系统财务管理部 | E25: 预算管理中心 | G25: S2职能系统－财经线/预算及职能系统财务管理部/预算管理中心 | H25: 43762 | I25: 社会招聘 | J25: 财经类－FN | K25: 预算管理 | L25: S6 | N25: T1# | Q25: U,G | U25: 30766.2 | V25: 0.083333 | W25: CNY | X25: 1 | Y25: 30214.76 | Z25: 0 | AA25: 92298.6 | AB25: 98570 | AC25: 41985 | AF25: 0 | AG25: 232853.6 | AH25: 7.7066176 | AI25: 232853.6 | AJ25: 7.7066176 | AK25: 6.3170649 | AQ25: 232853.6 | AR25: 7.7066176 | AS25: 0.92457256 | BL25: 1 | BM25: 27535 | BN25: 0 | BO25: 29840 | BP25: O,G | BQ25: T1# | BR25: 192300 | BS25: 6.9838388 | BT25: 59550 | BU25: 251850 | BV25: 9.1465408 | BY25: 251850 | BZ25: 9.1465408 | CP25: 预算及职能系统财务管理部 | CQ25: 5,3 | CR25: 6 | CS25: T1# | CT25: N
... A39: wayneChang(常阳) | C39: 74666760 | D39: 预算及职能系统财务管理部 | E39: 预算管理中心 | G39: S2职能系统－财经线/预算及职能系统财务管理部/预算管理中心 | H39: 43256 | I39: 社会招聘 | J39: 财经类－FN | K39: 预算管理 | L39: S10 | N39: T1 | Q39: U,G | U39: 35677.4 | V39: 0.083333 | W39: CNY | X39: 1 | Y39: 34145.86 | Z39: 0 | AA39: 35677.4 | AB39: 86825 | AC39: 0 | AF39: 0 | AG39: 122502.4 | AH39: 3.5876209 | AI39: 122502.4 | AJ39: 3.5876209 | AK39: 3.5876209 | AQ39: 122502.4 | AR39: 3.5876209 | AS39: 0.9608785 | BL39: 1 | BM39: 28695 | BN39: 0 | BO39: 29060 | BP39: G,G | BQ39: T1 | BR39: 88665 | BS39: 3.0899111 | BT39: 38825 | BU39: 127490 | BV39: 4.4429343 | BY39: 127490 | BZ39: 4.4429343 | CP39: 预算及职能系统财务管理部 | CQ39: 3,1 | CR39: 10 | CS39: T1 | CT39: N
A40: kevinQian(钱峰阳) | C40: 91424281 | D40: 风险管理和内部控制 | E40: WXG风控中心 | G40: S2职能系统－财经线/风险管理和内部控制/WXG风控中心 | H40: 45377 | I40: 社会招聘 | J40: 财经类－FN | K40: 风险管理 | L40: S8 | N40: T2 | Q40: G,O | U40: 46653.7 | V40: 0.083333 | W40: CNY | X40: 0.767123 | Y40: 44279.38 | Z40: 0 | AA40: 35789.13 | AB40: 0 | AC40: 0 | AF40: 0 | AG40: 35789.13 | AH40: 0.80825725 | AI40: 35789.13 | AJ40: 0.80825725 | AK40: 0.80825725 | AQ40: 35789.13 | AR40: 0.80825725 | BM40: 0 | BN40: 0 | BO40: 0 | BR40: 0 | BT40: 0 | BU40: 0 | BY40: 0 | CP40: 风险管理和内部控制 | CQ40: 5,3 | CR40: 8 | CS40: T2 | CT40: N
A41: ariaZeng(曾璐莉) | C41: 88685121 | D41: 财经IT管理部 | E41: 业务开发中心 | G41: S2职能系统－财经线/财经IT管理部/业务开发中心 | H41: 36550 | I41: 社会招聘 | J41: 技术研发类－TRD | K41: 应用开发 | L41: T11 | N41: T1 | Q41: G,G | U41: 54850.25 | V41: 0.083333 | W41: CNY | X41: 1 | Y41: 50436.78 | Z41: 0 | AA41: 109700.5 | AB41: 123525 | AC41: 82735 | AF41: 0 | AG41: 315960.5 | AH41: 6.264486 | AI41: 315960.5 | AJ41: 6.264486 | AK41: 4.6241156 | AQ41: 315960.5 | AR41: 6.264486 | AS41: 0.94781989 | BL41: 1 | BM41: 46005 | BN41: 0 | BO41: 47660 | BP41: O,O | BQ41: T1 | BR41: 255790 | BS41: 5.5600478 | BT41: 77565 | BU41: 333355 | BV41: 7.2460602 | BY41: 333355 | BZ41: 7.2460602 | CP41: 财经IT管理部 | CQ41: 3,3 | CR41: 11 | CS41: T1 | CT41: N
A42: seanShi(施博力) | C42: 13692542 | D42: 财会及报告管理部 | E42: 账务中心 | G42: S2职能系统－财经线/财会及报告管理部/账务中心 | H42: 43674 | I42: 社会招聘 | J42: 财经类－FN | K42: 会计 | L42: S6 | N42: T1# | Q42: G,G | U42: 23356.65 | V42: 0.083333 | W42: CNY | X42: 1 | Y42: 21832.3 | Z42: 0 | AA42: 46713.3 | AB42: 71115 | AC42: 29115 | AF42: 0 | AG42: 146943.3 | AH42: 6.730546 | AI42: 146943.3 | AJ42: 6.730546 | AK42: 5.3969715 | AQ42: 146943.3 | AR42: 6.730546 | AS42: 1.12209 | BL42: 1 | BM42: 19835 | BN42: 0 | BO42: 20055 | BP42: G,G | BQ42: T1# | BR42: 104160 | BS42: 5.2513234 | BT42: 26795 | BU42: 130955 | BV42: 6.6022183 | BY42: 130955 | BZ42: 6.6022183 | CP42: 财会及报告管理部 | CQ42: 3,3 | CR42: 6 | CS42: T1# | CT42: N
A43: kennethShi(施彪志) | C43: 83510684 | D43: FiT财务管理 | E43: 业务支持与分析中心 | G43: S2职能系统－财经线/FiT财务管理/业务支持与分析中心 | H43: 37145 | I43: 社会招聘 | J43: 财经类－FN | K43: 财务管理 | L43: S6 | N43: T1# | Q43: G,G | U43: 37008.1 | V43: 0.083333 | W43: CNY | X43: 1 | Y43: 34065.36 | Z43: 0 | AA43: 74016.2 | AB43: 111945 | AC43: 71085 | AF43: 0 | AG43: 257046.2 | AH43: 7.5456769 | AI43: 257046.2 | AJ43: 7.5456769 | AK43: 5.458953 | AQ43: 257046.2 | AR43: 7.5456769 | AS43: 1.0672903 | BL43: 1 | BM43: 32010 | BN43: 0 | BO43: 32285 | BP43: O,G | BQ43: T1# | BR43: 196995 | BS43: 6.1541706 | BT43: 43845 | BU43: 240840 | BV43: 7.5238988 | BY43: 240840 | BZ43: 7.5238988 | CP43: FiT财务管理 | CQ43: 3,3 | CR43: 6 | CS43: T1# | CT43: N
A44: dianeGuo(郭怡) | C44: 34945004 | D44: CSIG财务管理 | E44: 产品财务管理中心 | G44: S2职能系统－财经线/CSIG财务管理/产品财务管理中心 | H44: 40737 | I44: 社会招聘 | J44: 财经类－FN | K44: 财务管理 | L44: S5 | N44: T2 | Q44: G,G | U44: 19312.85 | V44: 0.083333 | W44: CNY | X44: 1 | Y44: 18658.16 | Z44: 0 | AA44: 38625.7 | AB44: 27795 | AC44: 0 | AF44: 0 | AG44: 66420.7 | AH44: 3.5598741 | AI44: 66420.7 | AJ44: 3.5598741 | AK44: 3.5598741 | AQ44: 66420.7 | AR44: 3.5598741 | AS44: 1.1443952 | BL44: 1 | BM44: 15915 | BN44: 0 | BO44: 17085 | BP44: G,G | BQ44: T2 | BR44: 58040 | BS44: 3.646874 | BT44: 0 | BU44: 58040 | BV44: 3.646874 | BY44: 58040 | BZ44: 3.646874 | CP44: CSIG财务管理 | CQ44: 3,3 | CR44: 5 | CS44: T2 | CT44: N
A45: geraldJiang(江立) | C45: 47476377 | D45: 财经投资并购及管理部 | E45: 财经投资并购及管理部 | G45: S2职能系统－财经线/财经投资并购及管理部 | H45: 39276 | I45: 高校招聘 | J45: 财经类－FN | K45: 投资并购 | L45: S9 | N45: T2 | Q45: G,G | U45: 42167.25 | V45: 0.083333 | W45: CNY | X45: 1 | Y45: 41478.02 | Z45: 0 | AA45: 84334.5 | AB45: 52235 | AC45: 0 | AF45: 0 | AG45: 136569.5 | AH45: 3.2925752 | AI45: 136569.5 | AJ45: 3.2925752 | AK45: 3.2925752 | AQ45: 136569.5 | AR45: 3.2925752 | AS45: 0.9049132 | BL45: 1 | BM45: 36430 | BN45: 0 | BO45: 36930 | BP45: G,O | BQ45: T2 | BR45: 150920 | BS45: 4.1427395 | BT45: 0 | BU45: 150920 | BV45: 4.1427395 | BY45: 150920 | BZ45: 4.1427395 | CP45: 财经投资并购及管理部 | CQ45: 3,3 | CR45: 9 | CS45: T2 | CT45: N
A46: samanthaLu(卢娇) | C46: 16699560 | D46: CDG财务管理 | E46: 综合财务管理中心 | G46: S2职能系统－财经线/CDG财务管理/综合财务管理中心 | H46: 40499 | I46: 社会招聘 | J46: 财经类－FN | K46: 财务管理 | L46: S9 | N46: T2 | Q46: G,G | U46: 52890.75 | V46: 0.083333 | W46: CNY | X46: 1 | Y46: 52143.33 | Z46: 0 | AA46: 105781.5 | AB46: 71240 | AC46: 0 | AF46: 0 | AG46: 177021.5 | AH46: 3.3949021 | AI46: 177021.5 | AJ46: 3.3949021 | AK46: 3.3949021 | AQ46: 177021.5 | AR46: 3.3949021 | AS46: 0.88774855 | BL46: 1 | BM46: 47065 | BN46: 0 | BO46: 47475 | BP46: O,G | BQ46: T2 | BR46: 199405 | BS46: 4.2368002 | BT46: 0 | BU46: 199405 | BV46: 4.2368002 | BY46: 199405 | BZ46: 4.2368002 | CP46: CDG财务管理 | CQ46: 3,3 | CR46: 9 | CS46: T2 | CT46: N
A47: amandaHuang(黄琪) | C47: 53009758 | D47: 应收账款管理中心 | E47: 应收管理1组 | G47: S2职能系统－财经线/应收账款管理中心/应收管理1组 | H47: 42236 | I47: 社会招聘 | J47: 财经类－FN | K47: 会计 | L47: S9 | N47: T2 | Q47: G,G | U47: 40910.55 | V47: 0.083333 | W47: CNY | X47: 1 | Y47: 38691.58 | Z47: 0 | AA47: 81821.1 | AB47: 44380 | AC47: 0 | AF47: 0 | AG47: 126201.1 | AH47: 3.26172 | AI47: 126201.1 | AJ47: 3.26172 | AK47: 3.26172 | AQ47: 126201.1 | AR47: 3.26172 | AS47: 1.0202191 | BL47: 1 | BM47: 36280 | BN47: 0 | BO47: 39725 | BP47: G,G | BQ47: T2 | BR47: 123700 | BS47: 3.4095921 | BT47: 0 | BU47: 123700 | BV47: 3.4095921 | BY47: 123700 | BZ47: 3.4095921 | CP47: 应收账款管理中心 | CQ47: 3,3 | CR47: 9 | CS47: T2 | CT47: N
A48: rebeccaQin(秦娟茜) | C48: 73675670 | D48: 可持续社会价值事业部财务管理 | E48: 可持续社会价值事业部财务管理 | G48: S2职能系统－财经线/可持续社会价值事业部财务管理 | H48: 42222 | I48: 高校招聘 | J48: 财经类－FN | K48: 财务管理 | L48: S12 | M48: L1-2 | N48: T1# | Q48: G,O | U48: 74713.15 | V48: 0.083333 | W48: CNY | X48: 1 | Y48: 73759.27 | Z48: 0 | AA48: 224139.45 | AB48: 225785 | AC48: 105815 | AF48: 15650 | AG48: 555739.45 | AH48: 7.5345031 | AI48: 571389.45 | AJ48: 7.7466798 | AK48: 6.3120805 | AQ48: 571389.45 | AR48: 7.7466798 | AS48: 1.0907085 | BL48: 1 | BM48: 66850 | BN48: 0 | BO48: 70875 | BP48: O,G | BQ48: T1# | BR48: 429750 | BS48: 6.4285714 | BT48: 94120 | BU48: 523870 | BV48: 7.8364996 | BY48: 523870 | BZ48: 7.8364996 | CP48: 可持续社会价值事业部财务管理 | CQ48: 5,3 | CR48: 12 | CS48: T1# | CT48: N
A49: stephenGao(高霖) | C49: 90270227 | D49: 董事会办公室 | E49: 董事会办公室 | G49: S2职能系统－财经线/董事会办公室 | H49: 37912 | I49: 社会招聘 | J49: 财经类－FN | K49: 公司秘书 | L49: S10 | N49: T1# | Q49: G,G | U49: 57296.75 | V49: 0.083333 | W49: CNY | X49: 1 | Y49: 52389.44 | Z49: 0 | AA49: 114593.5 | AB49: 175805 | AC49: 85420 | AF49: 0 | AG49: 375818.5 | AH49: 7.1735544 | AI49: 375818.5 | AJ49: 7.1735544 | AK49: 5.5430732 | AQ49: 375818.5 | AR49: 7.1735544 | AS49: 1.1033852 | BL49: 1 | BM49: 46200 | BN49: 0 | BO49: 49720 | BP49: G,G | BQ49: T1# | BR49: 268260 | BS49: 5.8064935 | BT49: 72345 | BU49: 340605 | BV49: 7.3724026 | BY49: 340605 | BZ49: 7.3724026 | CP49: 董事会办公室 | CQ49: 3,3 | CR49: 10 | CS49: T1# | CT49: N
A50: aaliyahZheng(郑英红) | C50: 22423058 | D50: IEG财务管理 | E50: IEG Global Finance | G50: S2职能系统－财经线/IEG财务管理/IEG Global Finance | H50: 37919 | I50: 社会招聘 | J50: 财经类－FN | K50: 财务管理 | M50: L3-2 | N50: T1# | Q50: G,G | U50: 69269.75 | V50: 0.083333 | W50: CNY | X50: 1 | Y50: 66474.84 | Z50: 0 | AA50: 138539.5 | AB50: 210995 | AC50: 121000 | AF50: 35580 | AG50: 470534.5 | AH50: 7.0783848 | AI50: 506114.5 | AJ50: 7.6136249 | AK50: 5.7933874 | AQ50: 506114.5 | AR50: 7.6136249 | AS50: 0.99965336 | BL50: 1 | BM50: 61615 | BN50: 0 | BO50: 64965 | BP50: G,O | BQ50: T1# | BR50: 402995 | BS50: 6.540534 | BT50: 103295 | BU50: 506290 | BV50: 8.2169926 | BY50: 506290 | BZ50: 8.2169926 | CP50: IEG财务管理 | CQ50: 3,3 | CR50: L3-2 | CS50: T1# | CT50: N
A51: walterQian(钱豪彤) | C51: 64672773 | D51: 预算及职能系统财务管理部 | E51: S系统财务管理组 | G51: S2职能系统－财经线/预算及职能系统财务管理部/S系统财务管理组 | H51: 39998 | I51: 高校招聘 | J51: 财经类－FN | K51: 预算管理 | L51: S9 | N51: T1# | Q51: G,O | U51: 56008.55 | V51: 0.083333 | W51: CNY | X51: 1 | Y51: 53386.03 | Z51: 0 | AA51: 168025.65 | AB51: 172480 | AC51: 64985 | AF51: 0 | AG51: 405490.65 | AH51: 7.5954449 | AI51: 405490.65 | AJ51: 7.5954449 | AK51: 6.3781789 | AQ51: 405490.65 | AR51: 7.5954449 | AS51: 1.9558685 | BL51: 1 | BM51: 50355 | BN51: 0 | BO51: 51325 | BP51: G,U | BQ51: T1# | BR51: 207320 | BS51: 4.1171681 | BT51: 0 | BU51: 207320 | BV51: 4.1171681 | BY51: 207320 | BZ51: 4.1171681 | CP51: 预算及职能系统财务管理部 | CQ51: 5,3 | CR51: 9 | CS51: T1# | CT51: N
A52: juliaLiao(廖雪瑶) | C52: 31719584 | D52: 税务部 | E52: 印章及文档管理组 | G52: S2职能系统－财经线/税务部/印章及文档管理组 | H52: 39421 | I52: 高校招聘 | J52: 财经类－FN | K52: 税务 | L52: S8 | N52: T2 | Q52: G,G | U52: 28976.2 | V52: 0.083333 | W52: CNY | X52: 1 | Y52: 27708.19 | Z52: 0 | AA52: 57952.4 | AB52: 34945 | AC52: 0 | AF52: 0 | AG52: 92897.4 | AH52: 3.3527055 | AI52: 92897.4 | AJ52: 3.3527055 | AK52: 3.3527055 | AQ52: 92897.4 | AR52: 3.3527055 | AS52: 1.1078338 | BL52: 1 | BM52: 24100 | BN52: 0 | BO52: 26240 | BP52: U,O | BQ52: T2 | BR52: 83855 | BS52: 3.4794606 | BT52: 0 | BU52: 83855 | BV52: 3.4794606 | BY52: 83855 | BZ52: 3.4794606 | CP52: 税务部 | CQ52: 3,3 | CR52: 8 | CS52: T2 | CT52: N
A53: marcusWei(魏松坚) | C53: 76307882 | D53: 财经IT管理部 | E53: 业务开发中心 | G53: S2职能系统－财经线/财经IT管理部/业务开发中心 | H53: 41314 | I53: 社会招聘 | J53: 技术研发类－TRD | K53: 应用开发 | L53: T7 | N53: T1 | Q53: G,G | U53: 31298 | V53: 0.083333 | W53: CNY | X53: 1 | Y53: 29306.23 | Z53: 0 | AA53: 62596 | AB53: 72315 | AC53: 38065 | AF53: 0 | AG53: 172976 | AH53: 5.9023627 | AI53: 172976 | AJ53: 5.9023627 | AK53: 4.6034922 | AQ53: 172976 | AR53: 5.9023627 | AS53: 1.2019735 | BL53: 1 | BM53: 27970 | BN53: 0 | BO53: 30180 | BP53: G,G | BQ53: T1 | BR53: 90595 | BS53: 3.2390061 | BT53: 53315 | BU53: 143910 | BV53: 5.1451555 | BY53: 143910 | BZ53: 5.1451555 | CP53: 财经IT管理部 | CQ53: 3,3 | CR53: 7 | CS53: T1 | CT53: N
...

Sheet 年终奖分配明细表-海外
A1: 分配模式：人民币 (Currency: CNY) | AC1: ='年终奖分配明细表-国内'!AC1 | AE1: ='年终奖分配明细表-国内'!AE1 | AP1: ='年终奖分配明细表-国内'!AP1 | AV1: ='年终奖分配明细表-国内'!AV1 | AX1: ='年终奖分配明细表-国内'!AX1 | AZ1: ='年终奖分配明细表-国内'!AZ1
AC2: ='年终奖分配明细表-国内'!AC2 | AE2: ='年终奖分配明细表-国内'!AE2 | AP2: ='年终奖分配明细表-国内'!AP2 | AV2: ='年终奖分配明细表-国内'!AV2 | AX2: ='年终奖分配明细表-国内'!AX2 | AZ2: ='年终奖分配明细表-国内'!AZ2
A3: 请勿隐藏绿色可调整列 | U3: 总额度 (Total) | AC3: ='年终奖分配明细表-国内'!AC3 | AE3: ='年终奖分配明细表-国内'!AE3 | AP3: ='年终奖分配明细表-国内'!AP3 | AV3: ='年终奖分配明细表-国内'!AV3 | AX3: ='年终奖分配明细表-国内'!AX3 | AZ3: ='年终奖分配明细表-国内'!AZ3
A4: Please DO NOT hide the Green column ! | U4: 已用额度 (Assigned) | AC4: ='年终奖分配明细表-国内'!AC4 | AE4: ='年终奖分配明细表-国内'!AE4 | AP4: ='年终奖分配明细表-国内'!AP4 | AV4: ='年终奖分配明细表-国内'!AV4 | AX4: ='年终奖分配明细表-国内'!AX4 | AZ4: ='年终奖分配明细表-国内'!AZ4
U5: 剩余额度 (Remaining) | AC5: ='年终奖分配明细表-国内'!AC5 | AE5: ='年终奖分配明细表-国内'!AE5 | AP5: ='年终奖分配明细表-国内'!AP5 | AV5: ='年终奖分配明细表-国内'!AV5 | AX5: ='年终奖分配明细表-国内'!AX5 | AZ5: ='年终奖分配明细表-国内'!AZ5
AP6: ='年终奖分配明细表-国内'!AP6
A7: 请勿删除第一行到第七行！！！
E8: ="@@CURRENCY_CNY" | AC8: ='年终奖分配明细表-国内'!AC8 | AE8: ='年终奖分配明细表-国内'!AE8 | AP8: ='年终奖分配明细表-国内'!AP8 | AV8: ='年终奖分配明细表-国内'!AV8 | AX8: ='年终奖分配明细表-国内'!AX8 | AZ8: ='年终奖分配明细表-国内'!AZ8
A9: 2 | G9: @@CD_g1qT4RWZn8PvzqzsvsSlZ1HoevUBl8dinYL8/H7Cw9JN1xdebvU/xUsX4kOF/8om | AB9: =SUM(AA14:AA20)+SUM(AC14:AC20) | AD9: =SUM(AE14:AE20) | AO9: =SUM(AP14:AP20) | AU9: =SUM(AV14:AV20) | AW9: =SUM(AX14:AX20) | AY9: =SUM(AZ14:AZ20)
H10: 基本信息 (Basic Info) | AC10: 本次奖金 (Bonus of This Year) | AO10: ="本次"&AP1 | AQ10: 本次合计 (Total of This Year) | BA10: 备注信息 (Remarks) | BG10: 辅助信息 (Additional Info) | BP10: 上年度参考信息 (Reference Info of Last Year) | CG10: 包信息 (Pool Info) | CI10: 自定义标签 (Custom Labels)
A11: Name | B11: Legal Name | C11: Staff ID | D11: Department | E11: Sub Organization of the Department | F11: 2nd-Level Org. Under Department | G11: Organization | H11: Onboarding Date | I11: Employment Type | J11: Job function | K11: Position | L11: Professional grade | M11: Managerial grade | N11: Talent Tier | O11: 2024 Talent Tier | P11: Talent Tier Change in Last 2 Years | Q11: 2025 H1/H2 Performance Ratings | R11: 2025 H1/H2 Customized Performance Ratings | S11: 2024 H1/H2 Performance Ratings | T11: Performance Change in Last 2 Years | U11: Current Monthly Salary (CNY) | V11: Target Bonus % | W11: Payroll Currency | X11: Time Proration Factor | Y11: Base Amount of Annual Bonus (CNY) | Z11: Base Amount of Target Bonus (CNY) | AA11: Target Bonus (T) (CNY) | AB11: Suggested Target Bonus (CNY) | AC11: Actual Target Bonus (CNY) | AD11: =IF(ISBLANK(AD12),"预留",AD12)&CHAR(10)&"Suggestion"&CHAR(10)&"(CNY)" | AE11: =IF(ISBLANK(AD12),"预留",AD12)&CHAR(10)&"Submission"&CHAR(10)&"(CNY)" | AF11: Total Project Bonus (CNY) | AG11: T+T0 Bonus (CNY) | AH11: T+T0 Bonus Index | AI11: Target+Project Bonus Amount (CNY) | AJ11: T+T0+Project Bonus Index | AK11: Suggested T+T0+Project Bonus Index | AL11: Vs. 2024 T+T0+Project Bonus | AM11: Target+Project Bonus Index | AN11: Suggested Target+Project Bonus Index | AO11: Incremental Profit Sharing Incentive Suggestion(CNY) (CNY) | AP11: =AO12&CHAR(10)&"Submission"&CHAR(10)&"(CNY)" | AQ11: Total Bonus Payout (CNY) | AR11: Total Payout Index (China) | AS11: Vs. 2024 Total Bonus Payout | AT11: Total Payout Index (Overseas) | AU11: =IF(ISBLANK(AU12),"预留",AU12)&CHAR(10)&"Suggestion"&CHAR(10)&"(CNY)" | AV11: =AU12&CHAR(10)&"Submission"&CHAR(10)&"(CNY)" | AW11: =IF(ISBLANK(AW12),"预留",AW12)&CHAR(10)&"Suggestion"&CHAR(10)&"(CNY)" | AX11: =AW12&CHAR(10)&"Submission"&CHAR(10)&"(CNY)" | AY11: =IF(ISBLANK(AY12),"预留",AY12)&CHAR(10)&"Suggestion"&CHAR(10)&"(CNY)" | AZ11: =AY12&CHAR(10)&"Submission"&CHAR(10)&"(CNY)" | BA11: Allocation Remarks | BB11: Historical Remarks | BC11: C&B G Remarks | BD11: Remarks from HRBP | BE11: Compensation-Performance Consistency | BF11: Allocation Alert | BG11: Promised Bonus (CNY) | BH11: Bonus Paid During the Year (CNY) | BI11: Remarks about Paid Bonus | BJ11: Non-deductible Leave Days % | BK11: Leave Days Remarks | BL11: Time Proration Factor of 2024 Annual Bonus | BM11: Base Amount of 2024 Annual Bonus (CNY) | BN11: Base Amount of 2024 Target Bonus (CNY) | BO11: Monthly Salary in 2024 (CNY) | BP11: 2024 H1/H2 Performance Ratings | BQ11: 2024 Talent Tier | BR11: 2024 Target Bonus (CNY) | BS11: 2024 T+T0 Bonus Index | BT11: 2024 Total Project Bonus (CNY) | BU11: 2024 Actual Target+Project Bonus (CNY) | BV11: 2024 T+T0+Project Bonus Index | BW11: 2024 Target+Project Bonus Index | BX11: 2024 Incremental Incentive (CNY) | BY11: 2024 Total Bonus Payout (CNY) | BZ11: 2024 Total Payout Index (China) | CA11: 2024 Total Payout Index (Overseas) | CB11: 2024 Service Bonus (CNY) | CC11: 2024 One- time Incremental Incentive (CNY) | CD11: 2024 Special Grant (CNY) | CE11: 2024 Non-deductible Leave Days % | CF11: 2024 Salary Structure Change | CG11: Pool name | CH11: Pool Owner | CI11: Salary Structure Change | CJ11: Sheet Split Tag | CK11: Region | CL11: Country/Region | CM11: Continent Region | CN11: LCY Exchange Rate | CO11: Termination/Transfer Label | CP11: Organization Label | CQ11: Performance Label | CR11: Job Grade Label | CS11: Talent Tier Label | CT11: New Job System Label | CU11: Serious violations of the Sunshine Code of Conduct | CV11: Good Overall Performance Rating with Underperform Contribution or Conduct Rating | CW11: Backup Label 2 | CX11: Backup Label 3 | CY11: Backup Label 4 | CZ11: Backup Label 5 | DA11: Backup Label 6 | DB11: Backup Label 7 | DC11: Backup Label 8
A12: @Name | D12: ="@@CR_12" | AC12: ="@B_"&AC8 | AE12: ="@B_"&AE8 | AP12: ="@B_"&AP8 | AV12: ="@B_"&AV8 | AX12: ="@B_"&AX8 | AZ12: ="@B_"&AZ8 | BA12: ="@Remark"
A13: 中英文名 | B13: 真实姓名 | C13: 员工ID | D13: 部门 | E13: 部门下一级组织 | F13: 部门下二级组织 | G13: 组织全称 | H13: 入职日期 | I13: 应聘类别 | J13: 发展通道 | K13: 专业职位 | L13: 专业职级 | M13: 管理职级 | N13: 2025 人才梯队 | O13: 2024 人才梯队 | P13: 两年梯队变化 | Q13: 2025绩效 H1/H2 | R13: 2025自定义绩效 H1/H2 | S13: 2024绩效 H1/H2 | T13: 两年绩效变化 | U13: 目前月薪 (CNY) | V13: 浮动比例 | W13: 发薪币种 | X13: 年终奖 时间系数 | Y13: 年终奖 基数 (CNY) | Z13: Target Bonus基数 (CNY) | AA13: 绩效奖金 (T) (CNY) | AB13: 下发 Target Bonus (CNY) | AC13: 提交 Target Bonus (CNY) | AD13: ="下发"&CHAR(10)&IF(ISBLANK(AE1),"预留Q",AE1)&"(CNY)" | AE13: ="提交"&CHAR(10)&IF(ISBLANK(AE1),"预留R",AE1)&"(CNY)" | AF13: 项目奖金 合计 (CNY) | AG13: (T+T0) 金额 (CNY) | AH13: (T+T0) 系数 | AI13: (Target Bonus+项目奖)金额 (CNY) | AJ13: (T+T0+项目奖) 系数 | AK13: 下发建议 (T+T0+项目奖) 系数 | AL13: VS 2024 (T+T0+项目奖) 金额 | AM13: (Target Bonus+项目奖)系数 | AN13: 下发建议 (Target Bonus+项目奖)系数 | AO13: ="下发"&CHAR(10)&AP1&"(CNY)" | AP13: ="提交"&CHAR(10)&AP1&"(CNY)" | AQ13: 合计金额 (CNY) | AR13: 国内合计系数 | AS13: VS 2024 合计金额 | AT13: 海外合计系数 | AU13: ="下发"&CHAR(10)&AV1&"(CNY)" | AV13: ="提交"&CHAR(10)&AV1&"(CNY)" | AW13: ="下发"&CHAR(10)&AX1&"(CNY)" | AX13: ="提交"&CHAR(10)&AX1&"(CNY)" | AY13: ="下发"&CHAR(10)&AZ1&"(CNY)" | AZ13: ="提交"&CHAR(10)&AZ1&"(CNY)" | BA13: 当前环节 分配备注 | BB13: 前序环节 分配备注 | BC13: 薪酬经理备注 | BD13: BP备注 | BE13: 薪酬与评价 匹配度 | BF13: 分配规则 校验信息 | BG13: 承诺奖金 (CNY) | BH13: 已发放奖金 (CNY) | BI13: 已发放奖金备注 | BJ13: 长假期天数占比(未影响时间系数) | BK13: 假期备注 | BL13: 2024 年终奖 时间系数 | BM13: 2024 年终奖 基数 (CNY) | BN13: 2024 Target Bonus基数 (CNY) | BO13: 2024月薪 (CNY) | BP13: 2024绩效 H1/H2 | BQ13: 2024 人才梯队 | BR13: 2024 Target Bonus 金额 (CNY) | BS13: 2024 (T+T0) 系数 | BT13: 2024 项目奖合计 (CNY) | BU13: 2024 (Target Bonus+项目奖)金额(CNY) | BV13: 2024 (T+T0+项目奖) 系数 | BW13: 2024 (Target Bonus+项目奖)系数 | BX13: 2024 增量激励 (如有) (CNY) | BY13: 2024 合计金额 (CNY) | BZ13: 2024 国内合计系数 | CA13: 2024 海外合计系数 | CB13: 2024 服务奖(CNY) | CC13: 2024增量项目激励 (如有) (CNY) | CD13: 2024年末特别授予(如有) (CNY) | CE13: 2024 长假期天数占比(未影响时间系数) | CF13: 2024全年 薪酬结构 变化标识 | CG13: 包名称 | CH13: 包负责人 | CI13: 全年 薪酬结构 变化标识 | CJ13: 拆表标签 | CK13: 地区分类 | CL13: 国家/地区 | CM13: 区域 | CN13: 本币汇率 | CO13: 离职/调动 标签 | CP13: 组织标签 | CQ13: 绩效标签 | CR13: 职级标签 | CS13: 梯队标签 | CT13: 试点体系标签 | CU13: 是否阳光行为违规 | CV13: 绩效综合G且业绩/行为评级U | CW13: 补充标签2 | CX13: 补充标签3 | CY13: 补充标签4 | CZ13: 补充标签5 | DA13: 补充标签6 | DB13: 补充标签7 | DC13: 补充标签8
A14: edwardXu(徐帆国) | C14: 57792341 | D14: 风险管理和内部控制 | E14: WXG风控中心 | G14: S2职能系统－财经线/风险管理和内部控制/WXG风控中心 | H14: 39707 | I14: 社会招聘 | J14: 财经类－FN | K14: 风险管理 | L14: S9 | N14: T1# | Q14: U,G | U14: 34220.45 | V14: 0.083333 | W14: CNY | X14: 1 | Y14: 32767.06 | Z14: 0 | AA14: 34220.45 | AF14: 0 | AG14: 147200.45 | AH14: 4.4923301 | AJ14: 4.4923301 | AK14: 4.4923301 | AQ14: 147200.45 | AR14: 4.4923301 | AS14: 0.64760427 | BL14: 1 | BM14: 30610 | BN14: 0 | BO14: 33125 | BP14: G,G | BQ14: T1# | BS14: 5.927638 | BT14: 45855 | BV14: 7.4256779 | BY14: 227300 | BZ14: 7.4256779 | CP14: 风险管理和内部控制 | CQ14: 3,1 | CR14: 9 | CS14: T1# | CT14: N
A15: savannahZhong(钟倩思) | C15: 78647818 | D15: 审计监察 | E15: 金融审计组 | G15: S2职能系统－财经线/审计监察/金融审计组 | H15: 45139 | I15: 高校招聘 | J15: 财经类－FN | K15: 风险管理 | L15: S5 | N15: T1# | Q15: G,U | U15: 23014.25 | V15: 0.083333 | W15: CNY | X15: 1 | Y15: 21659.73 | Z15: 0 | AA15: 69042.75 | AF15: 0 | AG15: 169102.75 | AH15: 7.8072418 | AJ15: 7.8072418 | AK15: 6.6578739 | AQ15: 169102.75 | AR15: 7.8072418 | AS15: 21.652081 | BL15: 0.41643836 | BM15: 18765 | BN15: 0 | BO15: 18765 | BP15: N,G | BQ15: T1# | BS15: 0.41620037 | BT15: 0 | BV15: 0.41620037 | BY15: 7810 | BZ15: 0.41620037 | CP15: 审计监察 | CQ15: 5,3 | CR15: 5 | CS15: T1# | CT15: N
A16: emmaZheng(郑苑) | C16: 37559092 | D16: 财会及报告管理部 | E16: 应收管理中心 | G16: S2职能系统－财经线/财会及报告管理部/应收管理中心 | H16: 41779 | I16: 社会招聘 | J16: 财经类－FN | K16: 会计 | L16: S11 | N16: T1# | Q16: G,G | U16: 53212.6 | V16: 0.083333 | W16: CNY | X16: 1 | Y16: 50216.55 | Z16: 0 | AA16: 106425.2 | AF16: 0 | AG16: 340800.2 | AH16: 6.7866112 | AJ16: 6.7866112 | AK16: 5.4371557 | AQ16: 340800.2 | AR16: 6.7866112 | AS16: 1.0573678 | BL16: 1 | BM16: 44240 | BN16: 0 | BO16: 46890 | BP16: G,G | BQ16: T1# | BS16: 5.3264014 | BT16: 86670 | BV16: 7.2854882 | BY16: 322310 | BZ16: 7.2854882 | CP16: 财会及报告管理部 | CQ16: 3,3 | CR16: 11 | CS16: T1# | CT16: N
A17: edwardJia(贾平华) | C17: 14198066 | D17: FiT财务管理 | E17: 业务支持与分析中心 | G17: S2职能系统－财经线/FiT财务管理/业务支持与分析中心 | H17: 37710 | I17: 社会招聘 | J17: 财经类－FN | K17: 财务管理 | L17: S6 | N17: T1 | Q17: O,G | U17: 27937.2 | V17: 0.083333 | W17: CNY | X17: 1 | Y17: 26626.57 | Z17: 0 | AA17: 111748.8 | AF17: 0 | AG17: 222923.8 | AH17: 8.3722312 | AJ17: 8.3722312 | AK17: 6.7747667 | AQ17: 222923.8 | AR17: 8.3722312 | AS17: 1.6884969 | BL17: 1 | BM17: 23850 | BN17: 0 | BO17: 25715 | BP17: G,G | BQ17: T1 | BS17: 3.3888889 | BT17: 51200 | BV17: 5.5356394 | BY17: 132025 | BZ17: 5.5356394 | CP17: FiT财务管理 | CQ17: 5,5 | CR17: 6 | CS17: T1 | CT17: N
A18: patrickJiang(姜彪国) | C18: 1336290 | D18: 风险管理和内部控制 | E18: CSIG风控中心 | G18: S2职能系统－财经线/风险管理和内部控制/CSIG风控中心 | H18: 42286 | I18: 社会招聘 | J18: 财经类－FN | K18: 风险管理 | L18: S9 | N18: T1 | Q18: O,G | U18: 54594.65 | V18: 0.083333 | W18: CNY | X18: 1 | Y18: 53257.31 | Z18: 0 | AA18: 109189.3 | AF18: 0 | AG18: 315779.3 | AH18: 5.9293137 | AJ18: 5.9293137 | AK18: 4.4958016 | AQ18: 315779.3 | AR18: 5.9293137 | AS18: 1.3897513 | BL18: 1 | BM18: 45345 | BN18: 0 | BO18: 49295 | BP18: G,G | BQ18: T1 | BS18: 3.4351086 | BT18: 71455 | BV18: 5.0109163 | BY18: 227220 | BZ18: 5.0109163 | CP18: 风险管理和内部控制 | CQ18: 3,3 | CR18: 9 | CS18: T1 | CT18: N
A19: chloeLin(林琴悦) | C19: 2185561 | D19: CSIG财务管理 | E19: 公线及费用财务管理中心 | G19: S2职能系统－财经线/CSIG财务管理/公线及费用财务管理中心 | H19: 43514 | I19: 社会招聘 | J19: 财经类－FN | K19: 财务管理 | L19: S8 | N19: T1 | Q19: O,G | U19: 46114.8 | V19: 0.083333 | W19: CNY | X19: 1 | Y19: 42227.05 | Z19: 0 | AA19: 138344.4 | AF19: 0 | AG19: 315254.4 | AH19: 7.4656979 | AJ19: 7.4656979 | AK19: 5.8512115 | AQ19: 315254.4 | AR19: 7.4656979 | AS19: 1.2007404 | BL19: 1 | BM19: 38825 | BN19: 0 | BO19: 40225 | BP19: G,G | BQ19: T1# | BS19: 5.6262717 | BT19: 44110 | BV19: 6.7623954 | BY19: 262550 | BZ19: 6.7623954 | CP19: CSIG财务管理 | CQ19: 5,3 | CR19: 8 | CS19: T1 | CT19: N
A20: abigailDong(董璐月) | C20: 15958390 | D20: 风险管理和内部控制 | E20: IEG风控中心 | G20: S2职能系统－财经线/风险管理和内部控制/IEG风控中心 | H20: 37998 | I20: 高校招聘 | J20: 财经类－FN | K20: 风险管理 | L20: S11 | N20: T1 | Q20: G,O | U20: 42014.3 | V20: 0.083333 | W20: CNY | X20: 1 | Y20: 40908.92 | Z20: 0 | AA20: 42014.3 | AF20: 0 | AG20: 146364.3 | AH20: 3.5778089 | AJ20: 3.5778089 | AK20: 3.5778089 | AQ20: 146364.3 | AR20: 3.5778089 | AS20: 0.5545993 | BL20: 1 | BM20: 35120 | BN20: 0 | BO20: 37910 | BP20: G,G | BQ20: T1# | BS20: 5.9212699 | BT20: 55955 | BV20: 7.5145216 | BY20: 263910 | BZ20: 7.5145216 | CP20: 风险管理和内部控制 | CQ20: 3,1 | CR20: 11 | CS20: T1 | CT20: N
A21: nicholasQiu(邱强) | C21: 19081982 | D21: 风险管理和内部控制 | E21: IEG风控中心 | G21: S2职能系统－财经线/风险管理和内部控制/IEG风控中心 | H21: 42461 | I21: 高校招聘 | J21: 财经类－FN | K21: 风险管理 | L21: S8 | N21: T2 | Q21: G,G | U21: 44043.7 | V21: 0.083333 | W21: CNY | X21: 1 | Y21: 41123.76 | Z21: 0 | AA21: 132131.1 | AF21: 0 | AG21: 183786.1 | AH21: 4.4690977 | AJ21: 4.4690977 | AK21: 4.4690977 | AQ21: 183786.1 | AR21: 4.4690977 | AS21: 1.1295317 | BL21: 1 | BM21: 35815 | BN21: 0 | BO21: 38760 | BP21: G,O | BQ21: T2 | BS21: 4.5430685 | BT21: 0 | BV21: 4.5430685 | BY21: 162710 | BZ21: 4.5430685 | CP21: 风险管理和内部控制 | CQ21: 5,3 | CR21: 8 | CS21: T2 | CT21: N
A22: matthewHou(侯勋宏) | C22: 81154958 | D22: 海外财经中心 | E22: 海外本地财务 | G22: S2职能系统－财经线/海外财经中心/海外本地财务 | H22: 41263 | I22: 社会招聘 | J22: 财经类－FN | K22: 财务管理 | L22: S11 | N22: T1 | Q22: G,G | U22: 51306.95 | V22: 0.083333 | W22: CNY | X22: 1 | Y22: 46207.44 | Z22: 0 | AA22: 102613.9 | AF22: 0 | AG22: 308873.9 | AH22: 6.6845058 | AJ22: 6.6845058 | AK22: 4.5615793 | AQ22: 308873.9 | AR22: 6.6845058 | AS22: 2.2710481 | BL22: 1 | BM22: 42530 | BN22: 0 | BO22: 44415 | BP22: U,O | BQ22: T1 | BS22: 3.1978603 | BT22: 0 | BV22: 3.1978603 | BY22: 136005 | BZ22: 3.1978603 | CP22: 海外财经中心 | CQ22: 3,3 | CR22: 11 | CS22: T1 | CT22: N
A23: lillianTian(田青) | C23: 21911153 | D23: 财经IT管理部 | E23: 平台建设中心 | G23: S2职能系统－财经线/财经IT管理部/平台建设中心 | H23: 43026 | I23: 高校招聘 | J23: 技术研发类－TRD | K23: 应用开发 | L23: T9 | N23: T1 | Q23: G,U | U23: 51577.2 | V23: 0.083333 | W23: CNY | X23: 1 | Y23: 47257.05 | Z23: 0 | AA23: 103154.4 | AF23: 0 | AG23: 292014.4 | AH23: 6.179277 | AJ23: 6.179277 | AK23: 4.8984099 | AQ23: 292014.4 | AR23: 6.179277 | AS23: 1.4390262 | BL23: 1 | BM23: 43545 | BN23: 0 | BO23: 46510 | BP23: G,G | BQ23: T1 | BS23: 3.2652429 | BT23: 60740 | BV23: 4.6601217 | BY23: 202925 | BZ23: 4.6601217 | CP23: 财经IT管理部 | CQ23: 3,3 | CR23: 9 | CS23: T1 | CT23: N
A24: louisYu(于梓) | C24: 60316002 | D24: 预算及职能系统财务管理部 | E24: 预算及职能系统财务管理部 | G24: S2职能系统－财经线/预算及职能系统财务管理部 | H24: 39619 | I24: 社会招聘 | J24: 财经类－FN | K24: 预算管理 | L24: S6 | N24: T1# | Q24: O,G | U24: 24152.75 | V24: 0.083333 | W24: CNY | X24: 1 | Y24: 22085.21 | Z24: 0 | AA24: 48305.5 | AF24: 0 | AG24: 171465.5 | AH24: 7.7638157 | AJ24: 7.7638157 | AK24: 5.8688824 | AQ24: 171465.5 | AR24: 7.7638157 | AS24: 1.0804379 | BL24: 1 | BM24: 21715 | BN24: 0 | BO24: 23560 | BP24: G,G | BQ24: T1# | BS24: 5.5664287 | BT24: 37825 | BV24: 7.3083122 | BY24: 158700 | BZ24: 7.3083122 | CP24: 预算及职能系统财务管理部 | CQ24: 3,3 | CR24: 6 | CS24: T1# | CT24: N
A25: ameliaNiu(牛佳娜) | C25: 82693967 | D25: 预算及职能系统财务管理部 | E25: 预算管理中心 | G25: S2职能系统－财经线/预算及职能系统财务管理部/预算管理中心 | H25: 43762 | I25: 社会招聘 | J25: 财经类－FN | K25: 预算管理 | L25: S6 | N25: T1# | Q25: U,G | U25: 30766.2 | V25: 0.083333 | W25: CNY | X25: 1 | Y25: 30214.76 | Z25: 0 | AA25: 92298.6 | AF25: 0 | AG25: 232853.6 | AH25: 7.7066176 | AJ25: 7.7066176 | AK25: 6.3170649 | AQ25: 232853.6 | AR25: 7.7066176 | AS25: 0.92457256 | BL25: 1 | BM25: 27535 | BN25: 0 | BO25: 29840 | BP25: O,G | BQ25: T1# | BS25: 6.9838388 | BT25: 59550 | BV25: 9.1465408 | BY25: 251850 | BZ25: 9.1465408 | CP25: 预算及职能系统财务管理部 | CQ25: 5,3 | CR25: 6 | CS25: T1# | CT25: N
... A39: wayneChang(常阳) | C39: 74666760 | D39: 预算及职能系统财务管理部 | E39: 预算管理中心 | G39: S2职能系统－财经线/预算及职能系统财务管理部/预算管理中心 | H39: 43256 | I39: 社会招聘 | J39: 财经类－FN | K39: 预算管理 | L39: S10 | N39: T1 | Q39: U,G | U39: 35677.4 | V39: 0.083333 | W39: CNY | X39: 1 | Y39: 34145.86 | Z39: 0 | AA39: 35677.4 | AF39: 0 | AG39: 122502.4 | AH39: 3.5876209 | AJ39: 3.5876209 | AK39: 3.5876209 | AQ39: 122502.4 | AR39: 3.5876209 | AS39: 0.9608785 | BL39: 1 | BM39: 28695 | BN39: 0 | BO39: 29060 | BP39: G,G | BQ39: T1 | BS39: 3.0899111 | BT39: 38825 | BV39: 4.4429343 | BY39: 127490 | BZ39: 4.4429343 | CP39: 预算及职能系统财务管理部 | CQ39: 3,1 | CR39: 10 | CS39: T1 | CT39: N
A40: kevinQian(钱峰阳) | C40: 91424281 | D40: 风险管理和内部控制 | E40: WXG风控中心 | G40: S2职能系统－财经线/风险管理和内部控制/WXG风控中心 | H40: 45377 | I40: 社会招聘 | J40: 财经类－FN | K40: 风险管理 | L40: S8 | N40: T2 | Q40: G,O | U40: 46653.7 | V40: 0.083333 | W40: CNY | X40: 0.767123 | Y40: 44279.38 | Z40: 0 | AA40: 35789.13 | AF40: 0 | AG40: 35789.13 | AH40: 0.80825725 | AJ40: 0.80825725 | AK40: 0.80825725 | AQ40: 35789.13 | AR40: 0.80825725 | BM40: 0 | BN40: 0 | BO40: 0 | BT40: 0 | BY40: 0 | CP40: 风险管理和内部控制 | CQ40: 5,3 | CR40: 8 | CS40: T2 | CT40: N
A41: ariaZeng(曾璐莉) | C41: 88685121 | D41: 财经IT管理部 | E41: 业务开发中心 | G41: S2职能系统－财经线/财经IT管理部/业务开发中心 | H41: 36550 | I41: 社会招聘 | J41: 技术研发类－TRD | K41: 应用开发 | L41: T11 | N41: T1 | Q41: G,G | U41: 54850.25 | V41: 0.083333 | W41: CNY | X41: 1 | Y41: 50436.78 | Z41: 0 | AA41: 109700.5 | AF41: 0 | AG41: 315960.5 | AH41: 6.264486 | AJ41: 6.264486 | AK41: 4.6241156 | AQ41: 315960.5 | AR41: 6.264486 | AS41: 0.94781989 | BL41: 1 | BM41: 46005 | BN41: 0 | BO41: 47660 | BP41: O,O | BQ41: T1 | BS41: 5.5600478 | BT41: 77565 | BV41: 7.2460602 | BY41: 333355 | BZ41: 7.2460602 | CP41: 财经IT管理部 | CQ41: 3,3 | CR41: 11 | CS41: T1 | CT41: N
A42: seanShi(施博力) | C42: 13692542 | D42: 财会及报告管理部 | E42: 账务中心 | G42: S2职能系统－财经线/财会及报告管理部/账务中心 | H42: 43674 | I42: 社会招聘 | J42: 财经类－FN | K42: 会计 | L42: S6 | N42: T1# | Q42: G,G | U42: 23356.65 | V42: 0.083333 | W42: CNY | X42: 1 | Y42: 21832.3 | Z42: 0 | AA42: 46713.3 | AF42: 0 | AG42: 146943.3 | AH42: 6.730546 | AJ42: 6.730546 | AK42: 5.3969715 | AQ42: 146943.3 | AR42: 6.730546 | AS42: 1.12209 | BL42: 1 | BM42: 19835 | BN42: 0 | BO42: 20055 | BP42: G,G | BQ42: T1# | BS42: 5.2513234 | BT42: 26795 | BV42: 6.6022183 | BY42: 130955 | BZ42: 6.6022183 | CP42: 财会及报告管理部 | CQ42: 3,3 | CR42: 6 | CS42: T1# | CT42: N
A43: kennethShi(施彪志) | C43: 83510684 | D43: FiT财务管理 | E43: 业务支持与分析中心 | G43: S2职能系统－财经线/FiT财务管理/业务支持与分析中心 | H43: 37145 | I43: 社会招聘 | J43: 财经类－FN | K43: 财务管理 | L43: S6 | N43: T1# | Q43: G,G | U43: 37008.1 | V43: 0.083333 | W43: CNY | X43: 1 | Y43: 34065.36 | Z43: 0 | AA43: 74016.2 | AF43: 0 | AG43: 257046.2 | AH43: 7.5456769 | AJ43: 7.5456769 | AK43: 5.458953 | AQ43: 257046.2 | AR43: 7.5456769 | AS43: 1.0672903 | BL43: 1 | BM43: 32010 | BN43: 0 | BO43: 32285 | BP43: O,G | BQ43: T1# | BS43: 6.1541706 | BT43: 43845 | BV43: 7.5238988 | BY43: 240840 | BZ43: 7.5238988 | CP43: FiT财务管理 | CQ43: 3,3 | CR43: 6 | CS43: T1# | CT43: N
A44: dianeGuo(郭怡) | C44: 34945004 | D44: CSIG财务管理 | E44: 产品财务管理中心 | G44: S2职能系统－财经线/CSIG财务管理/产品财务管理中心 | H44: 40737 | I44: 社会招聘 | J44: 财经类－FN | K44: 财务管理 | L44: S5 | N44: T2 | Q44: G,G | U44: 19312.85 | V44: 0.083333 | W44: CNY | X44: 1 | Y44: 18658.16 | Z44: 0 | AA44: 38625.7 | AF44: 0 | AG44: 66420.7 | AH44: 3.5598741 | AJ44: 3.5598741 | AK44: 3.5598741 | AQ44: 66420.7 | AR44: 3.5598741 | AS44: 1.1443952 | BL44: 1 | BM44: 15915 | BN44: 0 | BO44: 17085 | BP44: G,G | BQ44: T2 | BS44: 3.646874 | BT44: 0 | BV44: 3.646874 | BY44: 58040 | BZ44: 3.646874 | CP44: CSIG财务管理 | CQ44: 3,3 | CR44: 5 | CS44: T2 | CT44: N
A45: geraldJiang(江立) | C45: 47476377 | D45: 财经投资并购及管理部 | E45: 财经投资并购及管理部 | G45: S2职能系统－财经线/财经投资并购及管理部 | H45: 39276 | I45: 高校招聘 | J45: 财经类－FN | K45: 投资并购 | L45: S9 | N45: T2 | Q45: G,G | U45: 42167.25 | V45: 0.083333 | W45: CNY | X45: 1 | Y45: 41478.02 | Z45: 0 | AA45: 84334.5 | AF45: 0 | AG45: 136569.5 | AH45: 3.2925752 | AJ45: 3.2925752 | AK45: 3.2925752 | AQ45: 136569.5 | AR45: 3.2925752 | AS45: 0.9049132 | BL45: 1 | BM45: 36430 | BN45: 0 | BO45: 36930 | BP45: G,O | BQ45: T2 | BS45: 4.1427395 | BT45: 0 | BV45: 4.1427395 | BY45: 150920 | BZ45: 4.1427395 | CP45: 财经投资并购及管理部 | CQ45: 3,3 | CR45: 9 | CS45: T2 | CT45: N
A46: samanthaLu(卢娇) | C46: 16699560 | D46: CDG财务管理 | E46: 综合财务管理中心 | G46: S2职能系统－财经线/CDG财务管理/综合财务管理中心 | H46: 40499 | I46: 社会招聘 | J46: 财经类－FN | K46: 财务管理 | L46: S9 | N46: T2 | Q46: G,G | U46: 52890.75 | V46: 0.083333 | W46: CNY | X46: 1 | Y46: 52143.33 | Z46: 0 | AA46: 105781.5 | AF46: 0 | AG46: 177021.5 | AH46: 3.3949021 | AJ46: 3.3949021 | AK46: 3.3949021 | AQ46: 177021.5 | AR46: 3.3949021 | AS46: 0.88774855 | BL46: 1 | BM46: 47065 | BN46: 0 | BO46: 47475 | BP46: O,G | BQ46: T2 | BS46: 4.2368002 | BT46: 0 | BV46: 4.2368002 | BY46: 199405 | BZ46: 4.2368002 | CP46: CDG财务管理 | CQ46: 3,3 | CR46: 9 | CS46: T2 | CT46: N
A47: amandaHuang(黄琪) | C47: 53009758 | D47: 应收账款管理中心 | E47: 应收管理1组 | G47: S2职能系统－财经线/应收账款管理中心/应收管理1组 | H47: 42236 | I47: 社会招聘 | J47: 财经类－FN | K47: 会计 | L47: S9 | N47: T2 | Q47: G,G | U47: 40910.55 | V47: 0.083333 | W47: CNY | X47: 1 | Y47: 38691.58 | Z47: 0 | AA47: 81821.1 | AF47: 0 | AG47: 126201.1 | AH47: 3.26172 | AJ47: 3.26172 | AK47: 3.26172 | AQ47: 126201.1 | AR47: 3.26172 | AS47: 1.0202191 | BL47: 1 | BM47: 36280 | BN47: 0 | BO47: 39725 | BP47: G,G | BQ47: T2 | BS47: 3.4095921 | BT47: 0 | BV47: 3.4095921 | BY47: 123700 | BZ47: 3.4095921 | CP47: 应收账款管理中心 | CQ47: 3,3 | CR47: 9 | CS47: T2 | CT47: N
A48: rebeccaQin(秦娟茜) | C48: 73675670 | D48: 可持续社会价值事业部财务管理 | E48: 可持续社会价值事业部财务管理 | G48: S2职能系统－财经线/可持续社会价值事业部财务管理 | H48: 42222 | I48: 高校招聘 | J48: 财经类－FN | K48: 财务管理 | L48: S12 | M48: L1-2 | N48: T1# | Q48: G,O | U48: 74713.15 | V48: 0.083333 | W48: CNY | X48: 1 | Y48: 73759.27 | Z48: 0 | AA48: 224139.45 | AF48: 15650 | AG48: 555739.45 | AH48: 7.5345031 | AJ48: 7.7466798 | AK48: 6.3120805 | AQ48: 571389.45 | AR48: 7.7466798 | AS48: 1.0907085 | BL48: 1 | BM48: 66850 | BN48: 0 | BO48: 70875 | BP48: O,G | BQ48: T1# | BS48: 6.4285714 | BT48: 94120 | BV48: 7.8364996 | BY48: 523870 | BZ48: 7.8364996 | CP48: 可持续社会价值事业部财务管理 | CQ48: 5,3 | CR48: 12 | CS48: T1# | CT48: N
A49: stephenGao(高霖) | C49: 90270227 | D49: 董事会办公室 | E49: 董事会办公室 | G49: S2职能系统－财经线/董事会办公室 | H49: 37912 | I49: 社会招聘 | J49: 财经类－FN | K49: 公司秘书 | L49: S10 | N49: T1# | Q49: G,G | U49: 57296.75 | V49: 0.083333 | W49: CNY | X49: 1 | Y49: 52389.44 | Z49: 0 | AA49: 114593.5 | AF49: 0 | AG49: 375818.5 | AH49: 7.1735544 | AJ49: 7.1735544 | AK49: 5.5430732 | AQ49: 375818.5 | AR49: 7.1735544 | AS49: 1.1033852 | BL49: 1 | BM49: 46200 | BN49: 0 | BO49: 49720 | BP49: G,G | BQ49: T1# | BS49: 5.8064935 | BT49: 72345 | BV49: 7.3724026 | BY49: 340605 | BZ49: 7.3724026 | CP49: 董事会办公室 | CQ49: 3,3 | CR49: 10 | CS49: T1# | CT49: N
A50: aaliyahZheng(郑英红) | C50: 22423058 | D50: IEG财务管理 | E50: IEG Global Finance | G50: S2职能系统－财经线/IEG财务管理/IEG Global Finance | H50: 37919 | I50: 社会招聘 | J50: 财经类－FN | K50: 财务管理 | M50: L3-2 | N50: T1# | Q50: G,G | U50: 69269.75 | V50: 0.083333 | W50: CNY | X50: 1 | Y50: 66474.84 | Z50: 0 | AA50: 138539.5 | AF50: 35580 | AG50: 470534.5 | AH50: 7.0783848 | AJ50: 7.6136249 | AK50: 5.7933874 | AQ50: 506114.5 | AR50: 7.6136249 | AS50: 0.99965336 | BL50: 1 | BM50: 61615 | BN50: 0 | BO50: 64965 | BP50: G,O | BQ50: T1# | BS50: 6.540534 | BT50: 103295 | BV50: 8.2169926 | BY50: 506290 | BZ50: 8.2169926 | CP50: IEG财务管理 | CQ50: 3,3 | CR50: L3-2 | CS50: T1# | CT50: N
A51: walterQian(钱豪彤) | C51: 64672773 | D51: 预算及职能系统财务管理部 | E51: S系统财务管理组 | G51: S2职能系统－财经线/预算及职能系统财务管理部/S系统财务管理组 | H51: 39998 | I51: 高校招聘 | J51: 财经类－FN | K51: 预算管理 | L51: S9 | N51: T1# | Q51: G,O | U51: 56008.55 | V51: 0.083333 | W51: CNY | X51: 1 | Y51: 53386.03 | Z51: 0 | AA51: 168025.65 | AF51: 0 | AG51: 405490.65 | AH51: 7.5954449 | AJ51: 7.5954449 | AK51: 6.3781789 | AQ51: 405490.65 | AR51: 7.5954449 | AS51: 1.9558685 | BL51: 1 | BM51: 50355 | BN51: 0 | BO51: 51325 | BP51: G,U | BQ51: T1# | BS51: 4.1171681 | BT51: 0 | BV51: 4.1171681 | BY51: 207320 | BZ51: 4.1171681 | CP51: 预算及职能系统财务管理部 | CQ51: 5,3 | CR51: 9 | CS51: T1# | CT51: N
A52: juliaLiao(廖雪瑶) | C52: 31719584 | D52: 税务部 | E52: 印章及文档管理组 | G52: S2职能系统－财经线/税务部/印章及文档管理组 | H52: 39421 | I52: 高校招聘 | J52: 财经类－FN | K52: 税务 | L52: S8 | N52: T2 | Q52: G,G | U52: 28976.2 | V52: 0.083333 | W52: CNY | X52: 1 | Y52: 27708.19 | Z52: 0 | AA52: 57952.4 | AF52: 0 | AG52: 92897.4 | AH52: 3.3527055 | AJ52: 3.3527055 | AK52: 3.3527055 | AQ52: 92897.4 | AR52: 3.3527055 | AS52: 1.1078338 | BL52: 1 | BM52: 24100 | BN52: 0 | BO52: 26240 | BP52: U,O | BQ52: T2 | BS52: 3.4794606 | BT52: 0 | BV52: 3.4794606 | BY52: 83855 | BZ52: 3.4794606 | CP52: 税务部 | CQ52: 3,3 | CR52: 8 | CS52: T2 | CT52: N
A53: marcusWei(魏松坚) | C53: 76307882 | D53: 财经IT管理部 | E53: 业务开发中心 | G53: S2职能系统－财经线/财经IT管理部/业务开发中心 | H53: 41314 | I53: 社会招聘 | J53: 技术研发类－TRD | K53: 应用开发 | L53: T7 | N53: T1 | Q53: G,G | U53: 31298 | V53: 0.083333 | W53: CNY | X53: 1 | Y53: 29306.23 | Z53: 0 | AA53: 62596 | AF53: 0 | AG53: 172976 | AH53: 5.9023627 | AJ53: 5.9023627 | AK53: 4.6034922 | AQ53: 172976 | AR53: 5.9023627 | AS53: 1.2019735 | BL53: 1 | BM53: 27970 | BN53: 0 | BO53: 30180 | BP53: G,G | BQ53: T1 | BS53: 3.2390061 | BT53: 53315 | BV53: 5.1451555 | BY53: 143910 | BZ53: 5.1451555 | CP53: 财经IT管理部 | CQ53: 3,3 | CR53: 7 | CS53: T1 | CT53: N
...

Sheet 汇率
A1: 本币 | B1: 本币转CNY汇率
A2: CNY | B2: 1
A3: CNY | B3: 1
A4: SGD | B4: 5.4589
A5: USD | B5: 7.0789
